<!-- markdownlint-disable -->
# 2019-01-08 async




## async
### 初识async

> 参考
[Async/await - javascript.info](https://javascript.info/async-await)
[Understanding JavaScript’s async await](https://ponyfoo.com/articles/understanding-javascript-async-await)


async函数对Generator的改进

1. 内置执行器 - 自动调用next
2. 返回值是Promise

```js
function timeout(ms) {
  return new Promise((resolve) => {
    setTimeout(resolve, ms);
  });
}
// async函数返回的是promise对象，👇此函数返回值是undefined
async function timeout(ms) {
  await new Promise((resolve) => {
    setTimeout(resolve, ms);
  });
}
```

return的值会传递个then或者catch捕获
> await命令后面是一个 Promise 对象，返回该对象的结果。如果不是 Promise 对象，就直接返回对应的值。
> await后面的Promise如果变成reject状态，则reject的参数会被catch方法的回调函数接收到。(像加了return一样)


1.
```js
// async关键字的作用
// 1. funciton前的async表示返回函数始终返回一个promise，如果没有，会自动包裹在resolved promise中
// 2. 允许使用await

// 以下两个效果相同 
async function f() {
  return 1
}

async function f() {
  return Promise.resolve(1);
}
```

```js 
// 多个await是有一个reject则被catch，下面的会执行吗？
async function main() {
  try {
    const val1 = await firstStep();
    const val2 = await secondStep(val1);
    const val3 = await thirdStep(val1, val2);

    console.log('Final: ', val3);
  }
  catch (err) {
    console.error(err);
  }
}
```



1. await只能在async函数中可以使用，await使js等待，直到promise有了结果，才继续往下执行（异步的）
   await后面跟着的是一个promise(或thenable的方法)
```js
async function f() {
  console.log(1)
  let result = await new Promise((resolve, reject) => {
    setTimeout(() => {
      resolve(2)
    }, 1000)
  })
  console.log(result)
}

f()
```


```
Promise.resolve()是同步的？
```

try.. catch...不是不能捕获异步错误吗？？
```js
// try catch捕获错误，可捕获多个await
// 2. 也可以f().catch()捕获
async function f() {
  try {
    let response = await fetch('/no-user-here');
    let user = await response.json();
  } catch(err) {
    // catches errors both in fetch and response.json
    alert(err);
  }
}

f();
```


```js
// wait for the array of results
let results = await Promise.all([
  fetch(url1),
  fetch(url2),
  ...
]);
```
